<?xml version="1.0"?>

<robot xmlns:xacro="http://www.ros.org/wiki/xacro">

  <!-- Main quadrotor link -->
  <xacro:macro name="drone">
    <link name="base_link">
      <inertial>
        <mass value="1.477" />
        <origin xyz="0 0 0" />
        <inertia ixx="0.01152" ixy="0.0" ixz="0.0" iyy="0.01152" iyz="0.0" izz="0.0218" />
      </inertial>

      <visual>
        <origin xyz="0 0 0" rpy="0 0 0" />
        <geometry>
          <mesh filename="package://drone_description/meshes/drone.stl"/>
        </geometry>
      </visual>

      <collision>
        <origin xyz="0 0 0" rpy="0 0 0" />
        <geometry>
          <cylinder length="0.001" radius="0.301958"/>
        </geometry>
      </collision>
    </link>

<link name="brush">
      <inertial>
        <mass value="0.01" />
        <origin xyz="0 0 0" />
        <inertia ixx="0.01152" ixy="0.0" ixz="0.0" iyy="0.01152" iyz="0.0" izz="0.0218" />
      </inertial>

      <visual>
        <origin xyz="0 0 0" rpy="0 0 0" />
        <geometry>
          <mesh filename="package://drone_description/meshes/bush.stl"/>
        </geometry>
      </visual>

      <collision>
        <origin xyz="0 0 0" rpy="0 0 0" />
        <geometry>
          <box size="0.1 0.1 0.01"/>
        </geometry>
      </collision>
    </link>

<!-- <link name="sec">
  </link> -->
<!-- 
  <joint
    name="base_sec"
    type="continuous">
    <origin
      xyz="0 0 0"
      rpy="0 0 0" />
    <parent
      link="base_link" />
    <child
      link="sec" />
    <axis
      xyz="0 0 1" />
  </joint> -->

    <joint
    name="sec_brush"
    type="continuous">
    <origin
      xyz="0 0 -0.4"
      rpy="0 0 1.57" />
    <parent
      link="base_link" />
    <child
      link="brush" />
    <axis
      xyz="0 0 1" />
  </joint>


<link
    name="laser">
    <inertial>
      <origin
        xyz="0 0 0"
        rpy="0 0 0" />
      <mass
        value="0.01" />
      <inertia
        ixx="0.01"
        ixy="0"
        ixz="0"
        iyy="0.01"
        iyz="0"
        izz="0.01" />
    </inertial>
    <visual>
      <origin
        xyz="0 0 0"
        rpy="0 0 0" />
      <geometry>
        <mesh
          filename="package://perimeter/meshes/rplidar.stl" />
      </geometry>
      <material
        name="">
        <color
          rgba="0.792156862745098 0.819607843137255 0.933333333333333 1" />
      </material>
    </visual>
    <collision>
      <origin
        xyz="0 0 0"
        rpy="0 0 0" />
      <geometry>
        <mesh
          filename="package://perimeter/meshes/rplidar.stl" />
      </geometry>
    </collision>
  </link>
  <joint
    name="laser_base"
    type="fixed">
    <origin
      xyz="0 0 0.08"
      rpy="0 0 0" />
    <parent
      link="base_link" />
    <child
      link="laser" />
    <axis
      xyz="0 0 0" />
  </joint>

  <gazebo reference="base_link">
 <material>Gazebo/Yellow</material>
</gazebo>

  </xacro:macro>
</robot>
